Workbook

Sheet README
A1: TF Balance Component — mapping workbook
A2: Baseline 1.0 · executable reference data and deployment gates
A4: The three artefacts
A5: Build spec | B5: TF Balance Component — Implementation Specification. The 'what to build' contract.
A6: Mapping | B6: TF Balance Component — Mapping Workbook. This file: executable reference data and gates.
A7: Rationale | B7: Trade Finance — Contingent Liability & On-Balance-Sheet Lifecycle. The 'why': domain rationale, citations, worked entries.
A9: How to use this workbook
B10: The spec holds the narrative and the rules. This workbook holds the reference data a BA maintains and a developer loads.
B11: YELLOW cells with blue text are the bank's to complete. GREEN cells are formulas — do not overtype them.
B12: Two sheets need bank input before build: L0_Config_Register (column E) and L3_GL_Mapping.
B13: Two sheets are gates: L1_L2_Coverage (G2, blocks the build) and GL_Coverage (G1, blocks production).
A15: Three rules that must not be configured away
A16: 1 | B16: SG discharge is instrument-based, not amount-based — L1_Event_Catalogue (SG_REDEEMABLE is STATUS_ONLY; SG_RELEASE is full), tests T3, T4.
A17: 2 | B17: Acceptances and DPUs are on-balance sheet on both import and export; the memo pair is a shadow — Balance_Taxonomy (MEMO_ONLY in red), I6, I18, tests T6, T15, T27.
A18: 3 | B18: Accounting is never driven from tenorType alone — Tenor_Derivation with provenance, tests T9, T14.
A20: Sheet index
A21: Sheet | B21: Contents | C21: Rows
A22: L0_Config_Register | B22: Bank-configurable parameters. Presentation only — never event topology. | C22: =COUNTA(L0_Config_Register!B5:B600) -> 37
A23: Balance_Taxonomy | B23: Six balance classes, every balance type, and natural_side (drives derived posting_side). | C23: =COUNTA(Balance_Taxonomy!B5:B600) -> 51
A24: L1_Event_Catalogue | B24: Every event with movement_type, plus a live I17 resolution check. | C24: =COUNTA(L1_Event_Catalogue!B5:B600) -> 57
A25: L2_Balance_Movement | B25: LONG FORM. One row per event x posting_step x balance_type, with derived posting_side. | C25: =COUNTA(L2_Balance_Movement!B5:B600) -> 218
A26: L1_L2_Coverage | B26: Gate G2 — blocks the build if any event has no L2 definition. | C26: =COUNTA(L1_L2_Coverage!B5:B600) -> 11
A27: L3_GL_Mapping | B27: balance_type to GL account template. Row 5 is a worked example; replace it. | C27: =COUNTA(L3_GL_Mapping!B5:B600) -> 51
A28: GL_Coverage | B28: Gate G1 — blocks production until mapping coverage is 100%. | C28: =COUNTA(GL_Coverage!B5:B600) -> 5
A29: Tenor_Derivation | B29: tenorType as business classification, with derivation provenance fields. | C29: =COUNTA(Tenor_Derivation!B5:B600) -> 13
A30: L4_Risk_Obligor | B30: Obligor, type, recourse and limit per product/event. | C30: =COUNTA(L4_Risk_Obligor!B5:B600) -> 8
A31: L5_Regulatory_CCF | B31: CCF by class, with ccf_source separating CRE20 rules from internal-policy positions. | C31: =COUNTA(L5_Regulatory_CCF!B5:B600) -> 10
A32: Invariants | B32: I1A-I1C and I2-I22, sorted numerically; where each is enforced and what breaks without it. | C32: =COUNTA(Invariants!B5:B600) -> 24
A33: Amount_Basis | B33: Machine contract for amount resolution. Every L2 row carries a code from here. | C33: =COUNTA(Amount_Basis!B5:B600) -> 32
A34: Test_Scenarios | B34: 38 tests: T1-T22 business, T23-T33 technical, T34-T38 presentation, rounding, direction and idempotency retention. | C34: =COUNTA(Test_Scenarios!B5:B600) -> 38
A35: Controls_Reports | B35: Control report set and frequency. | C35: =COUNTA(Controls_Reports!B5:B600) -> 9
A37: Row counts are formulas, so they update as rows are added.

Sheet L0_Config_Register
A1: LAYER 0 — Bank configuration register
A2: Engine posture STRICT. Rule C3: no parameter may ASSERT an accounting-framework conclusion — it may only select which RULE applies (see I18, I19). Column E (yellow) is the bank's value to complete.
A4: Group | B4: Parameter | C4: Type | D4: Recommended / default | E4: Entity value (EDIT) | F4: Note | G4: v2 / spec ref
A5: GL mapping | B5: balance_type -> gl_account | C5: mapping table | D5: see L3_GL_Mapping sheet | F5: Resolution key: entity, balance_type, currency, product. | G5: §2.2
A6: GL mapping | B6: memo_pair_direction | C6: enum | D6: DR_CONTRA | F6: Entity-level. This is WHY posting_side is derived in L2 rather than stored literally. | G6: §2.1
A7: Accounting policy | B7: reporting_framework | C7: enum | D7: IFRS | F7: IFRS | LOCAL_GAAP | US_GAAP. Presentation only — never the event topology (E9/I18). | G7: spec §2.3
A8: Accounting policy | B8: presentation_treatment | C8: enum | D8: ON_BS_GROSS | F8: ON_BS_GROSS | NET_IF_ELIGIBLE | DISCLOSURE_ONLY. Selects the RULE, not the outcome: NET_IF_ELIGIBLE still nets only where the IAS 32.42 tests pass (I19). | G8: spec §2.3, §2.4
A9: Accounting policy | B9: commission_recognition | C9: enum | D9: OVER_TIME | G9: §9.2
A10: Accounting policy | B10: commission_materiality_threshold | C10: amount | D10: 250 | F10: Documented policy threshold, not a system accident. | G10: §9.2
A11: Accounting policy | B11: ifrs_scope default by product | C11: enum | D11: IFRS9_FGC for standbys/guarantees | F11: Drives the higher_of measurement rule. | G11: §9.3
A12: Accounting policy | B12: commitment_fee_drawdown_probable | C12: bool by product | D12: TRUE | F12: Probable -> defer into EIR; not probable -> time-proportion fee income. | G12: §9.2
A13: Amounts / rates | B13: margin_pct | C13: % by customer/product | D13: 20% | G13: §3.1
A14: Amounts / rates | B14: margin_application | C14: enum | D14: PRO_RATA | F14: FULL_ON_FIRST leaves the residual credit unmargined and makes the expiry release fail. Test T1. | G14: §3.5
A15: Amounts / rates | B15: sg_uplift_pct | C15: % | D15: 110% | G15: §4.2
A16: Amounts / rates | B16: sg_unlimited_policy_notional_pct | C16: % | D16: 120% | F16: Set liability_cap = UNLIMITED as a risk attribute where the carrier form is unlimited. | G16: §4.2
A17: Timing | B17: mail_float_grace_days | C17: days by place of expiry | D17: 15 | F17: Expiry trigger = expiry_date + this. NEVER + 21 days (Art. 14(c) runs from shipment). | G17: §3.9
A18: Timing | B18: examination_days_ucp | C18: banking days | D18: 5 | F18: UCP 600 Art. 16(d). | G18: §3.4
A19: Timing | B19: examination_days_urdg | C19: business days | D19: 5 | F19: URDG 758 Art. 20. Different calendar basis from UCP. | G19: §11
A20: Timing | B20: examination_days_isp | C20: business days | D20: 3 | F20: ISP98 Rule 5.01; beyond 7 unreasonable. | G20: §11
A21: Timing | B21: sg_redeemable_ageing_threshold_days | C21: days | D21: 30 | F21: Drives the highest-value SG control report. | G21: §4.4
A22: Timing | B22: awb_carrier_claim_period_days | C22: days | D22: 180 | F22: Air release has no original to return; own discharge trigger. | G22: §11
A23: Risk | B23: ecl_ead_factor | C23: % by product/rating | D23: 100% for issued DCs | F23: IFRS 9 expected drawdown. NEVER the Basel CCF (I9). | G23: §9.3
A24: Risk | B24: pd_lgd_stage_model | C24: model reference | G24: §9.3
A25: Risk | B25: lgd_uplift_silent_unnominated | C25: percentage points | D25: +15pp | F25: Keys on is_nominated_bank = FALSE, not on confirmation_type = SILENT. | G25: §6
A26: Risk | B26: limit_type by obligor_type x product | C26: mapping | D26: see L4_Risk_Obligor | G26: §10.1
A27: Regulatory | B27: ccf_class -> ccf_pct | C27: mapping | D27: see L5_Regulatory_CCF | G27: §10.3
A28: Regulatory | B28: ccf_source per class | C28: enum | D28: REGULATORY | INTERNAL_POLICY | F28: Regulatory returns read only REGULATORY (I10). | G28: §10.3
A29: Regulatory | B29: sg_reweights_linked_lc | C29: bool | D29: TRUE | F29: Internal policy position. CRE20 does not address it. | G29: §10.2
A30: Regulatory | B30: regulatory_netting_permitted | C30: bool | D30: FALSE | F30: Set TRUE only with written supervisory agreement. | G30: §10.2
A31: Regulatory | B31: local_return_line_mapping | C31: mapping | G31: §10.3
A32: Controls | B32: maker_checker_threshold by event | C32: amount | G32: §9.6
A33: Controls | B33: consent_gating_enabled by event | C33: bool | D33: TRUE for LC_AMD_DEC, SG_AMD_DEC | F33: Beneficiary consent for LC; CARRIER consent for SG. | G33: §3.2, §4.3
A34: Accounting policy | B34: netting_setoff_right_enforceable | C34: bool per counterparty/jurisdiction | D34: FALSE | F34: IAS 32.42(a). Must survive DEFAULT, INSOLVENCY and BANKRUPTCY of all parties. Legal opinion reference required — not an operator field. | G34: spec §2.4.1
A35: Accounting policy | B35: netting_settlement_intent | C35: enum | D35: NEITHER | F35: NET | SIMULTANEOUS | NEITHER. IAS 32.42(b). | G35: spec §2.4.1
A36: Accounting policy | B36: netting_policy_approved_by / _at | C36: text / date | F36: Evidenced accounting policy sign-off. Re-assessed EACH reporting date, not a permanent attribute. | G36: spec §2.4.1
A37: Amounts / rates | B37: currency_precision | C37: int by currency | D37: JPY 0 / USD 2 / KWD 3 | F37: I20. Applied BEFORE I1A is evaluated. Ledger core, not FX layer. | G37: spec §11
A38: Amounts / rates | B38: rounding_residual_account | C38: balance_type by entity | D38: ROUNDING_RESIDUAL | F38: I21. The residual must have a named home in the SAME journal. | G38: spec §11
A39: Controls | B39: idempotency_hot_lookup_days | C39: days | D39: 90 | F39: FAST-PATH CACHE HORIZON ONLY. Does NOT expire I15 uniqueness. A miss falls through to the permanent registry, never to 'not seen before'. | G39: spec §5.4
A40: Controls | B40: event_identity_retention | C40: policy | D40: TRANSACTION_LIFE + REGULATORY | F40: Permanent uniqueness registry for I15. Must never be shorter than the longest enabled undertaking tenor — 90 days is shorter than a 180-day buyer's usance. Gate G14. Test T38. | G40: spec §5.4
A41: Controls | B41: backdating_open_period_policy | C41: enum | D41: EFFECTIVE_DATE | F41: Governs the §5.4 backdating decision table. Prior-year always raises a PPA. | G41: spec §5.4

Sheet Balance_Taxonomy
A1: Balance taxonomy
A2: balance_class is structural (E9/I18). natural_side drives the derived posting_side in L2 (spec §2.2) — it is a POSTING concept. presentation_rule is a separate, REPORTING concept (spec §2.4, D6): FIXED, BY_SIGN (settlement accounts), or NET_IF_ELIGIBLE (gross unless the IAS 32.42 tests pass — I19). MEMO_ONLY never reaches the financials (I6).
A4: balance_class | B4: balance_type | C4: natural_side | D4: presentation_rule | E4: GL description | F4: Note | G4: v2 ref
A5: CONTINGENT | B5: LC_CUSTOMER_LIABILITY | C5: Dr | D5: FIXED | E5: Customers' Liability under Documentary Credits | F5: Bank's recourse against the applicant. NOT an on-BS liability. | G5: v2 §2.2
A6: CONTINGENT | B6: LC_OUTSTANDING | C6: Cr | D6: FIXED | E6: Documentary Credits Outstanding | F6: Bank's undertaking to the beneficiary. | G6: v2 §2.2
A7: CONTINGENT | B7: SG_CUSTOMER_LIABILITY | C7: Dr | D7: FIXED | E7: Customers' Liability under Shipping Guarantees | G7: v2 §4.2
A8: CONTINGENT | B8: SG_OUTSTANDING | C8: Cr | D8: FIXED | E8: Shipping Guarantees Outstanding | F8: Indemnity to the carrier. Beneficiary is the shipping line. | G8: v2 §4.2
A9: CONTINGENT | B9: CONFIRMATION_EXPOSURE | C9: Dr | D9: FIXED | E9: Issuing Bank Confirmation Exposure | F9: Obligor is the ISSUING BANK, not the exporter. | G9: v2 §7.1
A10: CONTINGENT | B10: CONFIRMATION_OUTSTANDING | C10: Cr | D10: FIXED | E10: Confirmation Undertakings Outstanding | F10: Drives off confirmed_amount, not lc_amount. | G10: v2 §7.2
A11: CONTINGENT | B11: REIMB_UNDERTAKING_EXPOSURE | C11: Dr | D11: FIXED | E11: Issuing Bank Reimbursement Exposure | F11: Only where an undertaking is issued (URR 725). | G11: v2 §7.7
A12: CONTINGENT | B12: REIMB_UNDERTAKING_OUTSTANDING | C12: Cr | D12: FIXED | E12: Reimbursement Undertakings Outstanding | F12: Agency-only reimbursing creates nothing. | G12: v2 §7.7
A13: ON_BALANCE_ASSET | B13: IMPORT_BILLS_RECEIVABLE | C13: Dr | D13: FIXED | E13: Import Bills Receivable — Applicant | F13: Sight honour. | G13: v2 §3.5
A14: ON_BALANCE_ASSET | B14: ACCEPTANCE_REIMB_RECEIVABLE_APPLICANT | C14: Dr | D14: NET_IF_ELIGIBLE | E14: Acceptance Reimbursement Receivable — Applicant | F14: Unconditional claim on the applicant, raised at LC_ACCEPT. | G14: v2 §3.7
A15: ON_BALANCE_ASSET | B15: ACCEPTANCE_REIMB_RECEIVABLE_ISSUING_BANK | C15: Dr | D15: NET_IF_ELIGIBLE | E15: Acceptance Reimbursement Receivable — Issuing Bank | F15: Export side. Art. 7(c) claim on the issuing bank. | G15: v2 §7.6
A16: ON_BALANCE_ASSET | B16: IMPORT_USANCE_FINANCING | C16: Dr | D16: FIXED | E16: Import Usance Financing | F16: BU-A bank-funded, and discounted acceptance. | G16: v2 §3.6
A17: ON_BALANCE_ASSET | B17: IMPORT_USANCE_RECEIVABLE_APPLICANT | C17: Dr | D17: NET_IF_ELIGIBLE | E17: Import Usance Receivable — Applicant | F17: BU-B. Paired with DUE_TO_REFINANCING_BANK. | G17: v2 §3.6
A18: ON_BALANCE_ASSET | B18: TRUST_RECEIPT_LOAN | C18: Dr | D18: FIXED | E18: Trust Receipt / Import Loan | F18: Post-payment financing against goods. NOT the same as BU financing. | G18: v2 §3.8
A19: ON_BALANCE_ASSET | B19: IMPORT_ADVANCE_FORCED | C19: Dr | D19: FIXED | E19: Import Advance — Forced (Overdue) | F19: Stage 3 and day-1 NPL on creation. | G19: v2 §3.8
... A26: ON_BALANCE_ASSET | B26: INTEREST_RECEIVABLE | C26: Dr | D26: FIXED | E26: Interest Receivable | F26: Effective interest. Suspend on Stage 3. | G26: v2 §9.4
A27: ON_BALANCE_ASSET | B27: NOSTRO | C27: Dr | D27: BY_SIGN | E27: Nostro | G27: —
A28: ON_BALANCE_ASSET_CONTRA | B28: UNEARNED_DISCOUNT | C28: Cr | D28: FIXED | E28: Unearned Discount | F28: Nets against a named asset. Accreted by DISC_ACCRETE. | G28: v2 §9.4
A29: ON_BALANCE_LIABILITY | B29: ACCEPTANCE_DPU_OUTSTANDING | C29: Cr | D29: NET_IF_ELIGIBLE | E29: Acceptances & DPU Outstanding | F29: THE accounting liability — not a contingent. | G29: v2 §3.7
A30: ON_BALANCE_LIABILITY | B30: CONFIRMED_ACCEPTANCE_DPU_OUTSTANDING | C30: Cr | D30: NET_IF_ELIGIBLE | E30: Confirmed Acceptances & DPU Outstanding | F30: Only where available_with = THIS_BANK. | G30: v2 §7.6
A31: ON_BALANCE_LIABILITY | B31: LC_SETTLEMENT_PAYABLE | C31: Cr | D31: FIXED | E31: LC Settlement Payable | F31: Honoured but not yet paid out. | G31: v2 §3.5
A32: ON_BALANCE_LIABILITY | B32: DUE_TO_REFINANCING_BANK | C32: Cr | D32: NET_IF_ELIGIBLE | E32: Due to Refinancing Bank — Buyer's Usance | F32: The interbank leg a single-IBL model hides. | G32: v2 §3.6
A33: ON_BALANCE_LIABILITY | B33: LC_CASH_MARGIN_DEPOSIT | C33: Cr | D33: FIXED | E33: LC Cash Margin Deposit | F33: Reclassification within customer deposits when internally funded. | G33: v2 §3.1
A34: ON_BALANCE_LIABILITY | B34: UNEARNED_COMMISSION_INCOME | C34: Cr | D34: FIXED | E34: Unearned Commission Income | F34: Subject to higher_of where ifrs_scope = IFRS9_FGC. | G34: v2 §9.2
A35: ON_BALANCE_LIABILITY | B35: PROVISION_OFFBS | C35: Cr | D35: FIXED | E35: Provision for Off-BS Credit Exposures | F35: IFRS 9 loss allowance. NOT a contra to the memo pair. | G35: v2 §9.3
A36: ON_BALANCE_LIABILITY | B36: CUSTOMER_CURRENT_ACCOUNT | C36: Cr | D36: BY_SIGN | E36: Customer Current Account | G36: —
A37: ON_BALANCE_LIABILITY | B37: BENEFICIARY_ACCOUNT | C37: Cr | D37: BY_SIGN | E37: Beneficiary Account | G37: —
A38: PROFIT_AND_LOSS | B38: FEE_COMMISSION_INCOME | C38: Cr | D38: FIXED | E38: Fee & Commission Income | G38: v2 §9.2
A39: PROFIT_AND_LOSS | B39: INTEREST_INCOME | C39: Cr | D39: FIXED | E39: Interest Income | F39: Includes the UPAS spread on BU-B. | G39: v2 §3.6
A40: PROFIT_AND_LOSS | B40: INTEREST_EXPENSE | C40: Dr | D40: FIXED | E40: Interest Expense — Refinancing Bank | F40: BU-B funding leg. | G40: v2 §3.6
A41: PROFIT_AND_LOSS | B41: IMPAIRMENT_CHARGE_OFFBS | C41: Dr | D41: FIXED | E41: Impairment Charge — Off-BS Credit Exposures | G41: v2 §9.3
A42: MEMO_ONLY | B42: ACCEPTANCE_SHADOW_DR | C42: Dr | D42: FIXED | E42: Acceptance Shadow — Customers' Liability | F42: MIS only. NEVER feeds the financials (I6). | G42: v2 §3.7
A43: MEMO_ONLY | B43: ACCEPTANCE_SHADOW_CR | C43: Cr | D43: FIXED | E43: Acceptance Shadow — Outstanding | F43: MIS only. | G43: v2 §3.7
A44: MEMO_ONLY | B44: CONFIRMED_ACCEPTANCE_SHADOW_DR | C44: Dr | D44: FIXED | E44: Confirmed Acceptance Shadow — Exposure | F44: MIS only. | G44: v2 §7.6
A45: MEMO_ONLY | B45: CONFIRMED_ACCEPTANCE_SHADOW_CR | C45: Cr | D45: FIXED | E45: Confirmed Acceptance Shadow — Outstanding | F45: MIS only. | G45: v2 §7.6
A46: MEMO_ONLY | B46: DOCUMENT_UNDER_EXAMINATION | C46: Dr | D46: FIXED | E46: Bills under LC — Received, Under Examination | F46: Art. 16 clock visibility. | G46: v2 §3.4
A47: MEMO_ONLY | B47: DOCUMENT_AT_PRESENTER_DISPOSAL | C47: Dr | D47: FIXED | E47: Bills Held at Presenter's Disposal | F47: Refused and held. | G47: v2 §3.4
...

Sheet L1_Event_Catalogue
A1: LAYER 1 — Business event catalogue
A2: Src: O = operator, M = inbound message, S = system-generated (fires unattended), B = batch. Every event carries exactly one movement_type and resolves to >=1 L2 row — invariant I17, asserted in column H.
A4: Side | B4: event_code | C4: Trigger | D4: Src | E4: movement_type | F4: Precondition / gate | G4: v2 ref | H4: L2 rows | I4: I17
A5: Import | B5: LC_ISSUE | C5: MT700 released | D5: O | E5: POST | F5: Limit approved. max_liability from Art. 30(a) amount tolerance ONLY, never 30(b) quantity. | G5: §3.1 | H5: =COUNTIF(L2_Balance_Movement!$B$5:$B$600,$B5) -> 8 | I5: =IF($H5>0,"OK","MISSING L2") -> OK
A6: Import | B6: LC_AMD_INC | C6: MT707 increase | D6: O | E6: POST | F6: Incremental commission deferred over REMAINING tenor. | G6: §3.2 | H6: =COUNTIF(L2_Balance_Movement!$B$5:$B$600,$B6) -> 4 | I6: =IF($H6>0,"OK","MISSING L2") -> OK
A7: Import | B7: LC_AMD_DEC | C7: MT707 decrease | D7: O | E7: POST | F7: BLOCKED until beneficiary consent recorded. Art. 10(a)/(c): silence is not acceptance. | G7: §3.2 | H7: =COUNTIF(L2_Balance_Movement!$B$5:$B$600,$B7) -> 2 | I7: =IF($H7>0,"OK","MISSING L2") -> OK
A8: Import | B8: LC_AMD_TENOR | C8: Expiry / tenor change | D8: O | E8: BATCH_RECALC | F8: Moves no amount but MUST re-run ECL, CCF bucket and limit expiry. Test T19. | G8: §3.2 | H8: =COUNTIF(L2_Balance_Movement!$B$5:$B$600,$B8) -> 1 | I8: =IF($H8>0,"OK","MISSING L2") -> OK
A9: Import | B9: LC_DOC_RCV | C9: Documents received | D9: O/M | E9: MEMO_ONLY | F9: Starts the Art. 16(d) five-banking-day clock. | G9: §3.4 | H9: =COUNTIF(L2_Balance_Movement!$B$5:$B$600,$B9) -> 2 | I9: =IF($H9>0,"OK","MISSING L2") -> OK
A10: Import | B10: LC_DOC_REFUSE | C10: Refusal notice sent | D10: O | E10: MEMO_ONLY | F10: Conforming notice within 5 banking days. Rejected if LC_DOC_PRECLUDED already fired. | G10: §3.4 | H10: =COUNTIF(L2_Balance_Movement!$B$5:$B$600,$B10) -> 2 | I10: =IF($H10>0,"OK","MISSING L2") -> OK
A11: Import | B11: LC_DOC_WAIVER | C11: Applicant waives discrepancies | D11: O | E11: NO_BALANCE_EFFECT | F11: Enables honour. Moves nothing itself. | G11: §3.4 | H11: =COUNTIF(L2_Balance_Movement!$B$5:$B$600,$B11) -> 1 | I11: =IF($H11>0,"OK","MISSING L2") -> OK
A12: Import | B12: LC_DOC_PRECLUDED | C12: 5 banking days lapse, no conforming refusal | D12: S | E12: BATCH_RECALC | F12: Art. 16(f). SYSTEM-GENERATED, fires unattended. Re-weights to 100%. | G12: §3.4 | H12: =COUNTIF(L2_Balance_Movement!$B$5:$B$600,$B12) -> 1 | I12: =IF($H12>0,"OK","MISSING L2") -> OK
A13: Import | B13: LC_PAY_RESERVE | C13: Paid under reserve / against indemnity | D13: O | E13: POST | F13: NOT an honour. Creates a recourse asset on the presenter. | G13: §3.4 | H13: =COUNTIF(L2_Balance_Movement!$B$5:$B$600,$B13) -> 4 | I13: =IF($H13>0,"OK","MISSING L2") -> OK
A14: Import | B14: LC_RESERVE_CALLED | C14: Reserve called, presenter refunds | D14: O | E14: POST | F14: Reinstates the contingent if still within validity. | G14: §3.4 | H14: =COUNTIF(L2_Balance_Movement!$B$5:$B$600,$B14) -> 4 | I14: =IF($H14>0,"OK","MISSING L2") -> OK
A15: Import | B15: LC_HONOUR_SIGHT | C15: Sight honour | D15: O | E15: POST | F15: Complying, waived, or precluded. Margin applied PRO RATA. | G15: §3.5 | H15: =COUNTIF(L2_Balance_Movement!$B$5:$B$600,$B15) -> 12 | I15: =IF($H15>0,"OK","MISSING L2") -> OK
A16: Import | B16: LC_HONOUR_BU_A | C16: BU honour, bank-funded | D16: O | E16: POST | F16: fundingParty = SELF. | G16: §3.6 | H16: =COUNTIF(L2_Balance_Movement!$B$5:$B$600,$B16) -> 6 | I16: =IF($H16>0,"OK","MISSING L2") -> OK
... A27: Import | B27: SG_ISSUE | C27: SG issued | D27: O | E27: POST | F27: linked_lc_id MANDATORY (I5). Policy notional where the carrier form is unlimited. | G27: §4.2 | H27: =COUNTIF(L2_Balance_Movement!$B$5:$B$600,$B27) -> 6 | I27: =IF($H27>0,"OK","MISSING L2") -> OK
A28: Import | B28: SG_AMD_INC | C28: SG increase | D28: O | E28: POST | G28: §4.3 | H28: =COUNTIF(L2_Balance_Movement!$B$5:$B$600,$B28) -> 2 | I28: =IF($H28>0,"OK","MISSING L2") -> OK
A29: Import | B29: SG_AMD_DEC | C29: SG decrease | D29: O | E29: POST | F29: Requires CARRIER consent, not the applicant's. | G29: §4.3 | H29: =COUNTIF(L2_Balance_Movement!$B$5:$B$600,$B29) -> 2 | I29: =IF($H29>0,"OK","MISSING L2") -> OK
A30: Import | B30: SG_REDEEMABLE | C30: Original B/L received | D30: O | E30: STATUS_ONLY | F30: STATUS ONLY. NO GL MOVEMENT. Test T3. | G30: §4.4 | H30: =COUNTIF(L2_Balance_Movement!$B$5:$B$600,$B30) -> 1 | I30: =IF($H30>0,"OK","MISSING L2") -> OK
A31: Import | B31: SG_RELEASE | C31: Original SG returned / carrier release / B/L surrendered | D31: O | E31: POST | F31: FULL amount, no residual. Test T4. | G31: §4.4 | H31: =COUNTIF(L2_Balance_Movement!$B$5:$B$600,$B31) -> 4 | I31: =IF($H31>0,"OK","MISSING L2") -> OK
A32: Import | B32: SG_CLAIM | C32: Carrier claims under the SG | D32: O | E32: POST | F32: Stage 3. May exceed booked notional if unlimited. | G32: §4.4 | H32: =COUNTIF(L2_Balance_Movement!$B$5:$B$600,$B32) -> 4 | I32: =IF($H32>0,"OK","MISSING L2") -> OK
A33: Import | B33: AWB_RELEASE | C33: Air release endorsed | D33: O | E33: POST | F33: Separate product. AWB is not a document of title. | G33: §11 | H33: =COUNTIF(L2_Balance_Movement!$B$5:$B$600,$B33) -> 2 | I33: =IF($H33>0,"OK","MISSING L2") -> OK
A34: Import | B34: AWB_DISCHARGE | C34: LC settled + endorsement evidence, or claim period lapsed | D34: O/B | E34: POST | F34: Do NOT reuse SG_RELEASE. Test T22. | G34: §11 | H34: =COUNTIF(L2_Balance_Movement!$B$5:$B$600,$B34) -> 2 | I34: =IF($H34>0,"OK","MISSING L2") -> OK
A35: Export | B35: EX_ADVISE | C35: LC advised | D35: O | E35: NO_BALANCE_EFFECT | F35: NO contingent. Art. 9(b) duties are operational. Test T11. | G35: §6 | H35: =COUNTIF(L2_Balance_Movement!$B$5:$B$600,$B35) -> 1 | I35: =IF($H35>0,"OK","MISSING L2") -> OK
A36: Export | B36: CNF_ADD | C36: Confirmation actually advised to the beneficiary | D36: O | E36: POST | F36: NEVER triggered by field 49 (I11). Test T10. | G36: §7.1 | H36: =COUNTIF(L2_Balance_Movement!$B$5:$B$600,$B36) -> 6 | I36: =IF($H36>0,"OK","MISSING L2") -> OK
A37: Export | B37: CNF_ADD_SILENT | C37: Silent confirmation added | D37: O | E37: POST | F37: confirmation_type = SILENT. LGD uplift keys on is_nominated_bank = FALSE. | G37: §6 | H37: =COUNTIF(L2_Balance_Movement!$B$5:$B$600,$B37) -> 6 | I37: =IF($H37>0,"OK","MISSING L2") -> OK
A38: Export | B38: CNF_AMD_INC | C38: Confirmation increase | D38: O | E38: POST | F38: Moves confirmed_amount, which may diverge from lc_amount (Art. 10(b)). | G38: §7.2 | H38: =COUNTIF(L2_Balance_Movement!$B$5:$B$600,$B38) -> 2 | I38: =IF($H38>0,"OK","MISSING L2") -> OK
A39: Export | B39: CNF_AMD_DEC | C39: Confirmation decrease | D39: O | E39: POST | F39: As above. | G39: §7.2 | H39: =COUNTIF(L2_Balance_Movement!$B$5:$B$600,$B39) -> 2 | I39: =IF($H39>0,"OK","MISSING L2") -> OK
A40: Export | B40: EX_DOC_RCV | C40: Documents presented | D40: O | E40: MEMO_ONLY | F40: Starts the examination clock. | G40: §7.3 | H40: =COUNTIF(L2_Balance_Movement!$B$5:$B$600,$B40) -> 2 | I40: =IF($H40>0,"OK","MISSING L2") -> OK
... A50: Export | B50: CNF_DISCOUNT | C50: Settles its own liability early | D50: O | E50: POST | F50: Without recourse. Obligor stays the issuing bank. | G50: §7.6 | H50: =COUNTIF(L2_Balance_Movement!$B$5:$B$600,$B50) -> 7 | I50: =IF($H50>0,"OK","MISSING L2") -> OK
A51: Export | B51: CNF_MATURE | C51: Confirmed acceptance matures | D51: O/B | E51: POST | G51: §7.6 | H51: =COUNTIF(L2_Balance_Movement!$B$5:$B$600,$B51) -> 6 | I51: =IF($H51>0,"OK","MISSING L2") -> OK
A52: Export | B52: CNF_REIMB | C52: Reimbursement received | D52: M | E52: POST | F52: Clears the issuing-bank claim. | G52: §7.4a | H52: =COUNTIF(L2_Balance_Movement!$B$5:$B$600,$B52) -> 2 | I52: =IF($H52>0,"OK","MISSING L2") -> OK
A53: Export | B53: CNF_EXPIRE | C53: expiry_date + mail_float_grace at the PLACE OF EXPIRY | D53: B | E53: POST | F53: Never + 21 days. | G53: §7.7 | H53: =COUNTIF(L2_Balance_Movement!$B$5:$B$600,$B53) -> 6 | I53: =IF($H53>0,"OK","MISSING L2") -> OK
A54: Export | B54: EX_REFIN | C54: This bank refinances the issuing bank | D54: O | E54: POST | F54: Separate FI lending product with its own credit approval. | G54: §7.5 | H54: =COUNTIF(L2_Balance_Movement!$B$5:$B$600,$B54) -> 3 | I54: =IF($H54>0,"OK","MISSING L2") -> OK
A55: Export | B55: RMB_UNDERTAKE | C55: Reimbursement undertaking issued (URR 725) | D55: O | E55: POST | F55: Agency-only reimbursing creates NOTHING. | G55: §7.7 | H55: =COUNTIF(L2_Balance_Movement!$B$5:$B$600,$B55) -> 4 | I55: =IF($H55>0,"OK","MISSING L2") -> OK
A56: Cross | B56: FEE_ACCRUE | C56: Period end | D56: B | E56: POST | G56: §9.2 | H56: =COUNTIF(L2_Balance_Movement!$B$5:$B$600,$B56) -> 2 | I56: =IF($H56>0,"OK","MISSING L2") -> OK
A57: Cross | B57: ECL_ASSESS | C57: Any balance-moving event, period end, rating change | D57: S/B | E57: POST | F57: MUST fire on LC_AMD_TENOR even though it moves no amount. | G57: §9.3 | H57: =COUNTIF(L2_Balance_Movement!$B$5:$B$600,$B57) -> 2 | I57: =IF($H57>0,"OK","MISSING L2") -> OK
A58: Cross | B58: INT_ACCRUE | C58: Period end, effective interest | D58: B | E58: POST | F58: Suspend on Stage 3 / non-accrual. | G58: §9.4 | H58: =COUNTIF(L2_Balance_Movement!$B$5:$B$600,$B58) -> 2 | I58: =IF($H58>0,"OK","MISSING L2") -> OK
A59: Cross | B59: DISC_ACCRETE | C59: Period end, unearned discount | D59: B | E59: POST | G59: §9.4 | H59: =COUNTIF(L2_Balance_Movement!$B$5:$B$600,$B59) -> 2 | I59: =IF($H59>0,"OK","MISSING L2") -> OK
A60: Cross | B60: FX_REVAL | C60: Period end | D60: B | E60: POST | F60: Contingent pairs revalue in tandem: nil P&L by construction. | G60: §9.5 | H60: =COUNTIF(L2_Balance_Movement!$B$5:$B$600,$B60) -> 2 | I60: =IF($H60>0,"OK","MISSING L2") -> OK
...

Sheet L2_Balance_Movement
A1: LAYER 2 — Balance movement (machine-loadable long form)
A2: One row per event_code x posting_step x balance_type. No combined codes, no pseudo-rows. posting_side is DERIVED from natural_side in Balance_Taxonomy (green formula) — never stored literally, because memo_pair_direction is entity-configurable.
A4: Side | B4: event_code | C4: posting_step | D4: step_seq | E4: balance_type | F4: movement | G4: posting_side (derived) | H4: amount_basis_code | I4: amount_basis (gloss) | J4: movement_type | K4: balance_type valid? | L4: basis code valid? | M4: posting-side integrity (G2B) | N4: amount-direction integrity (G13) | O4: v2 ref
A5: Import | B5: LC_ISSUE | C5: RAISE_CONTINGENT | D5: 1 | E5: LC_CUSTOMER_LIABILITY | F5: INCREASE | G5: {=IF(OR($F5="DERIVED_FROM_SIGN",$F5="MIRRORED"),"runtime",IFERROR(IF(INDEX(Balance_Taxonomy!$C$5:$C$400,MATCH($E5,Balance_Taxonomy!$B$5:$B$400,0))="Dr",IF($F5="INCREASE","Dr","Cr"),IF($F5="INCREASE","Cr","Dr")),"n/a"))} -> Dr | H5: MAX_LIABILITY | I5: max_liability | J5: POST | K5: =IF(OR($E5="—",LEFT($E5,1)="("),"n/a",IF(COUNTIF(Balance_Taxonomy!$B$5:$B$400,$E5)>0,"OK","UNKNOWN TYPE")) -> OK | L5: =IF(COUNTIF(Amount_Basis!$A$5:$A$100,$H5)>0,"OK","UNKNOWN CODE") -> OK | M5: =IF($F5="DERIVED_FROM_SIGN",IF($G5="runtime","OK","INVALID - must be runtime"),IF(OR($J5="POST",$J5="MEMO_ONLY"),IF(OR($G5="Dr",$G5="Cr"),"OK","INVALID - must derive"),IF(OR($G5="n/a",$G5="runtime"),"OK","INVALID - must be n/a"))) -> OK | N5: {=IF($J5="MIRROR",IF($F5="MIRRORED","OK","INVALID - MIRROR needs MIRRORED"),IF(IFERROR(INDEX(Amount_Basis!$D$5:$D$100,MATCH($H5,Amount_Basis!$A$5:$A$100,0)),"")="SIGNED",IF($F5="DERIVED_FROM_SIGN","OK","INVALID - SIGNED basis needs DERIVED_FROM_SIGN"),IF(OR($F5="INCREASE",$F5="DECREASE",$F5="—"),"OK","INVALID - static direction required")))} -> OK | O5: §3.1
A6: Import | B6: LC_ISSUE | C6: RAISE_CONTINGENT | D6: 1 | E6: LC_OUTSTANDING | F6: INCREASE | G6: {=IF(OR($F6="DERIVED_FROM_SIGN",$F6="MIRRORED"),"runtime",IFERROR(IF(INDEX(Balance_Taxonomy!$C$5:$C$400,MATCH($E6,Balance_Taxonomy!$B$5:$B$400,0))="Dr",IF($F6="INCREASE","Dr","Cr"),IF($F6="INCREASE","Cr","Dr")),"n/a"))} -> Cr | H6: MAX_LIABILITY | I6: max_liability | J6: POST | K6: =IF(OR($E6="—",LEFT($E6,1)="("),"n/a",IF(COUNTIF(Balance_Taxonomy!$B$5:$B$400,$E6)>0,"OK","UNKNOWN TYPE")) -> OK | L6: =IF(COUNTIF(Amount_Basis!$A$5:$A$100,$H6)>0,"OK","UNKNOWN CODE") -> OK | M6: =IF($F6="DERIVED_FROM_SIGN",IF($G6="runtime","OK","INVALID - must be runtime"),IF(OR($J6="POST",$J6="MEMO_ONLY"),IF(OR($G6="Dr",$G6="Cr"),"OK","INVALID - must derive"),IF(OR($G6="n/a",$G6="runtime"),"OK","INVALID - must be n/a"))) -> OK | N6: {=IF($J6="MIRROR",IF($F6="MIRRORED","OK","INVALID - MIRROR needs MIRRORED"),IF(IFERROR(INDEX(Amount_Basis!$D$5:$D$100,MATCH($H6,Amount_Basis!$A$5:$A$100,0)),"")="SIGNED",IF($F6="DERIVED_FROM_SIGN","OK","INVALID - SIGNED basis needs DERIVED_FROM_SIGN"),IF(OR($F6="INCREASE",$F6="DECREASE",$F6="—"),"OK","INVALID - static direction required")))} -> OK | O6: §3.1
A7: Import | B7: LC_ISSUE | C7: TAKE_MARGIN | D7: 2 | E7: CUSTOMER_CURRENT_ACCOUNT | F7: DECREASE | G7: {=IF(OR($F7="DERIVED_FROM_SIGN",$F7="MIRRORED"),"runtime",IFERROR(IF(INDEX(Balance_Taxonomy!$C$5:$C$400,MATCH($E7,Balance_Taxonomy!$B$5:$B$400,0))="Dr",IF($F7="INCREASE","Dr","Cr"),IF($F7="INCREASE","Cr","Dr")),"n/a"))} -> Dr | H7: MARGIN_TAKEN | I7: face x margin_pct | J7: POST | K7: =IF(OR($E7="—",LEFT($E7,1)="("),"n/a",IF(COUNTIF(Balance_Taxonomy!$B$5:$B$400,$E7)>0,"OK","UNKNOWN TYPE")) -> OK | L7: =IF(COUNTIF(Amount_Basis!$A$5:$A$100,$H7)>0,"OK","UNKNOWN CODE") -> OK | M7: =IF($F7="DERIVED_FROM_SIGN",IF($G7="runtime","OK","INVALID - must be runtime"),IF(OR($J7="POST",$J7="MEMO_ONLY"),IF(OR($G7="Dr",$G7="Cr"),"OK","INVALID - must derive"),IF(OR($G7="n/a",$G7="runtime"),"OK","INVALID - must be n/a"))) -> OK | N7: {=IF($J7="MIRROR",IF($F7="MIRRORED","OK","INVALID - MIRROR needs MIRRORED"),IF(IFERROR(INDEX(Amount_Basis!$D$5:$D$100,MATCH($H7,Amount_Basis!$A$5:$A$100,0)),"")="SIGNED",IF($F7="DERIVED_FROM_SIGN","OK","INVALID - SIGNED basis needs DERIVED_FROM_SIGN"),IF(OR($F7="INCREASE",$F7="DECREASE",$F7="—"),"OK","INVALID - static direction required")))} -> OK | O7: §3.1
A8: Import | B8: LC_ISSUE | C8: TAKE_MARGIN | D8: 2 | E8: LC_CASH_MARGIN_DEPOSIT | F8: INCREASE | G8: {=IF(OR($F8="DERIVED_FROM_SIGN",$F8="MIRRORED"),"runtime",IFERROR(IF(INDEX(Balance_Taxonomy!$C$5:$C$400,MATCH($E8,Balance_Taxonomy!$B$5:$B$400,0))="Dr",IF($F8="INCREASE","Dr","Cr"),IF($F8="INCREASE","Cr","Dr")),"n/a"))} -> Cr | H8: MARGIN_TAKEN | I8: face x margin_pct | J8: POST | K8: =IF(OR($E8="—",LEFT($E8,1)="("),"n/a",IF(COUNTIF(Balance_Taxonomy!$B$5:$B$400,$E8)>0,"OK","UNKNOWN TYPE")) -> OK | L8: =IF(COUNTIF(Amount_Basis!$A$5:$A$100,$H8)>0,"OK","UNKNOWN CODE") -> OK | M8: =IF($F8="DERIVED_FROM_SIGN",IF($G8="runtime","OK","INVALID - must be runtime"),IF(OR($J8="POST",$J8="MEMO_ONLY"),IF(OR($G8="Dr",$G8="Cr"),"OK","INVALID - must derive"),IF(OR($G8="n/a",$G8="runtime"),"OK","INVALID - must be n/a"))) -> OK | N8: {=IF($J8="MIRROR",IF($F8="MIRRORED","OK","INVALID - MIRROR needs MIRRORED"),IF(IFERROR(INDEX(Amount_Basis!$D$5:$D$100,MATCH($H8,Amount_Basis!$A$5:$A$100,0)),"")="SIGNED",IF($F8="DERIVED_FROM_SIGN","OK","INVALID - SIGNED basis needs DERIVED_FROM_SIGN"),IF(OR($F8="INCREASE",$F8="DECREASE",$F8="—"),"OK","INVALID - static direction required")))} -> OK | O8: §3.1
A9: Import | B9: LC_ISSUE | C9: DEFER_COMMISSION | D9: 3 | E9: CUSTOMER_CURRENT_ACCOUNT | F9: DECREASE | G9: {=IF(OR($F9="DERIVED_FROM_SIGN",$F9="MIRRORED"),"runtime",IFERROR(IF(INDEX(Balance_Taxonomy!$C$5:$C$400,MATCH($E9,Balance_Taxonomy!$B$5:$B$400,0))="Dr",IF($F9="INCREASE","Dr","Cr"),IF($F9="INCREASE","Cr","Dr")),"n/a"))} -> Dr | H9: COMMISSION_AMOUNT | I9: issuance commission | J9: POST | K9: =IF(OR($E9="—",LEFT($E9,1)="("),"n/a",IF(COUNTIF(Balance_Taxonomy!$B$5:$B$400,$E9)>0,"OK","UNKNOWN TYPE")) -> OK | L9: =IF(COUNTIF(Amount_Basis!$A$5:$A$100,$H9)>0,"OK","UNKNOWN CODE") -> OK | M9: =IF($F9="DERIVED_FROM_SIGN",IF($G9="runtime","OK","INVALID - must be runtime"),IF(OR($J9="POST",$J9="MEMO_ONLY"),IF(OR($G9="Dr",$G9="Cr"),"OK","INVALID - must derive"),IF(OR($G9="n/a",$G9="runtime"),"OK","INVALID - must be n/a"))) -> OK | N9: {=IF($J9="MIRROR",IF($F9="MIRRORED","OK","INVALID - MIRROR needs MIRRORED"),IF(IFERROR(INDEX(Amount_Basis!$D$5:$D$100,MATCH($H9,Amount_Basis!$A$5:$A$100,0)),"")="SIGNED",IF($F9="DERIVED_FROM_SIGN","OK","INVALID - SIGNED basis needs DERIVED_FROM_SIGN"),IF(OR($F9="INCREASE",$F9="DECREASE",$F9="—"),"OK","INVALID - static direction required")))} -> OK | O9: §3.1
A10: Import | B10: LC_ISSUE | C10: DEFER_COMMISSION | D10: 3 | E10: UNEARNED_COMMISSION_INCOME | F10: INCREASE | G10: {=IF(OR($F10="DERIVED_FROM_SIGN",$F10="MIRRORED"),"runtime",IFERROR(IF(INDEX(Balance_Taxonomy!$C$5:$C$400,MATCH($E10,Balance_Taxonomy!$B$5:$B$400,0))="Dr",IF($F10="INCREASE","Dr","Cr"),IF($F10="INCREASE","Cr","Dr")),"n/a"))} -> Cr | H10: COMMISSION_AMOUNT | I10: issuance commission | J10: POST | K10: =IF(OR($E10="—",LEFT($E10,1)="("),"n/a",IF(COUNTIF(Balance_Taxonomy!$B$5:$B$400,$E10)>0,"OK","UNKNOWN TYPE")) -> OK | L10: =IF(COUNTIF(Amount_Basis!$A$5:$A$100,$H10)>0,"OK","UNKNOWN CODE") -> OK | M10: =IF($F10="DERIVED_FROM_SIGN",IF($G10="runtime","OK","INVALID - must be runtime"),IF(OR($J10="POST",$J10="MEMO_ONLY"),IF(OR($G10="Dr",$G10="Cr"),"OK","INVALID - must derive"),IF(OR($G10="n/a",$G10="runtime"),"OK","INVALID - must be n/a"))) -> OK | N10: {=IF($J10="MIRROR",IF($F10="MIRRORED","OK","INVALID - MIRROR needs MIRRORED"),IF(IFERROR(INDEX(Amount_Basis!$D$5:$D$100,MATCH($H10,Amount_Basis!$A$5:$A$100,0)),"")="SIGNED",IF($F10="DERIVED_FROM_SIGN","OK","INVALID - SIGNED basis needs DERIVED_FROM_SIGN"),IF(OR($F10="INCREASE",$F10="DECREASE",$F10="—"),"OK","INVALID - static direction required")))} -> OK | O10: §3.1
A11: Import | B11: LC_ISSUE | C11: RAISE_ECL | D11: 4 | E11: IMPAIRMENT_CHARGE_OFFBS | F11: INCREASE | G11: {=IF(OR($F11="DERIVED_FROM_SIGN",$F11="MIRRORED"),"runtime",IFERROR(IF(INDEX(Balance_Taxonomy!$C$5:$C$400,MATCH($E11,Balance_Taxonomy!$B$5:$B$400,0))="Dr",IF($F11="INCREASE","Dr","Cr"),IF($F11="INCREASE","Cr","Dr")),"n/a"))} -> Dr | H11: ECL_AMOUNT | I11: ECL | J11: POST | K11: =IF(OR($E11="—",LEFT($E11,1)="("),"n/a",IF(COUNTIF(Balance_Taxonomy!$B$5:$B$400,$E11)>0,"OK","UNKNOWN TYPE")) -> OK | L11: =IF(COUNTIF(Amount_Basis!$A$5:$A$100,$H11)>0,"OK","UNKNOWN CODE") -> OK | M11: =IF($F11="DERIVED_FROM_SIGN",IF($G11="runtime","OK","INVALID - must be runtime"),IF(OR($J11="POST",$J11="MEMO_ONLY"),IF(OR($G11="Dr",$G11="Cr"),"OK","INVALID - must derive"),IF(OR($G11="n/a",$G11="runtime"),"OK","INVALID - must be n/a"))) -> OK | N11: {=IF($J11="MIRROR",IF($F11="MIRRORED","OK","INVALID - MIRROR needs MIRRORED"),IF(IFERROR(INDEX(Amount_Basis!$D$5:$D$100,MATCH($H11,Amount_Basis!$A$5:$A$100,0)),"")="SIGNED",IF($F11="DERIVED_FROM_SIGN","OK","INVALID - SIGNED basis needs DERIVED_FROM_SIGN"),IF(OR($F11="INCREASE",$F11="DECREASE",$F11="—"),"OK","INVALID - static direction required")))} -> OK | O11: §3.1
A12: Import | B12: LC_ISSUE | C12: RAISE_ECL | D12: 4 | E12: PROVISION_OFFBS | F12: INCREASE | G12: {=IF(OR($F12="DERIVED_FROM_SIGN",$F12="MIRRORED"),"runtime",IFERROR(IF(INDEX(Balance_Taxonomy!$C$5:$C$400,MATCH($E12,Balance_Taxonomy!$B$5:$B$400,0))="Dr",IF($F12="INCREASE","Dr","Cr"),IF($F12="INCREASE","Cr","Dr")),"n/a"))} -> Cr | H12: ECL_AMOUNT | I12: ECL | J12: POST | K12: =IF(OR($E12="—",LEFT($E12,1)="("),"n/a",IF(COUNTIF(Balance_Taxonomy!$B$5:$B$400,$E12)>0,"OK","UNKNOWN TYPE")) -> OK | L12: =IF(COUNTIF(Amount_Basis!$A$5:$A$100,$H12)>0,"OK","UNKNOWN CODE") -> OK | M12: =IF($F12="DERIVED_FROM_SIGN",IF($G12="runtime","OK","INVALID - must be runtime"),IF(OR($J12="POST",$J12="MEMO_ONLY"),IF(OR($G12="Dr",$G12="Cr"),"OK","INVALID - must derive"),IF(OR($G12="n/a",$G12="runtime"),"OK","INVALID - must be n/a"))) -> OK | N12: {=IF($J12="MIRROR",IF($F12="MIRRORED","OK","INVALID - MIRROR needs MIRRORED"),IF(IFERROR(INDEX(Amount_Basis!$D$5:$D$100,MATCH($H12,Amount_Basis!$A$5:$A$100,0)),"")="SIGNED",IF($F12="DERIVED_FROM_SIGN","OK","INVALID - SIGNED basis needs DERIVED_FROM_SIGN"),IF(OR($F12="INCREASE",$F12="DECREASE",$F12="—"),"OK","INVALID - static direction required")))} -> OK | O12: §3.1
A13: Import | B13: LC_AMD_INC | C13: RAISE_CONTINGENT | D13: 1 | E13: LC_CUSTOMER_LIABILITY | F13: INCREASE | G13: {=IF(OR($F13="DERIVED_FROM_SIGN",$F13="MIRRORED"),"runtime",IFERROR(IF(INDEX(Balance_Taxonomy!$C$5:$C$400,MATCH($E13,Balance_Taxonomy!$B$5:$B$400,0))="Dr",IF($F13="INCREASE","Dr","Cr"),IF($F13="INCREASE","Cr","Dr")),"n/a"))} -> Dr | H13: AMENDMENT_DELTA | I13: delta | J13: POST | K13: =IF(OR($E13="—",LEFT($E13,1)="("),"n/a",IF(COUNTIF(Balance_Taxonomy!$B$5:$B$400,$E13)>0,"OK","UNKNOWN TYPE")) -> OK | L13: =IF(COUNTIF(Amount_Basis!$A$5:$A$100,$H13)>0,"OK","UNKNOWN CODE") -> OK | M13: =IF($F13="DERIVED_FROM_SIGN",IF($G13="runtime","OK","INVALID - must be runtime"),IF(OR($J13="POST",$J13="MEMO_ONLY"),IF(OR($G13="Dr",$G13="Cr"),"OK","INVALID - must derive"),IF(OR($G13="n/a",$G13="runtime"),"OK","INVALID - must be n/a"))) -> OK | N13: {=IF($J13="MIRROR",IF($F13="MIRRORED","OK","INVALID - MIRROR needs MIRRORED"),IF(IFERROR(INDEX(Amount_Basis!$D$5:$D$100,MATCH($H13,Amount_Basis!$A$5:$A$100,0)),"")="SIGNED",IF($F13="DERIVED_FROM_SIGN","OK","INVALID - SIGNED basis needs DERIVED_FROM_SIGN"),IF(OR($F13="INCREASE",$F13="DECREASE",$F13="—"),"OK","INVALID - static direction required")))} -> OK | O13: §3.2
A14: Import | B14: LC_AMD_INC | C14: RAISE_CONTINGENT | D14: 1 | E14: LC_OUTSTANDING | F14: INCREASE | G14: {=IF(OR($F14="DERIVED_FROM_SIGN",$F14="MIRRORED"),"runtime",IFERROR(IF(INDEX(Balance_Taxonomy!$C$5:$C$400,MATCH($E14,Balance_Taxonomy!$B$5:$B$400,0))="Dr",IF($F14="INCREASE","Dr","Cr"),IF($F14="INCREASE","Cr","Dr")),"n/a"))} -> Cr | H14: AMENDMENT_DELTA | I14: delta | J14: POST | K14: =IF(OR($E14="—",LEFT($E14,1)="("),"n/a",IF(COUNTIF(Balance_Taxonomy!$B$5:$B$400,$E14)>0,"OK","UNKNOWN TYPE")) -> OK | L14: =IF(COUNTIF(Amount_Basis!$A$5:$A$100,$H14)>0,"OK","UNKNOWN CODE") -> OK | M14: =IF($F14="DERIVED_FROM_SIGN",IF($G14="runtime","OK","INVALID - must be runtime"),IF(OR($J14="POST",$J14="MEMO_ONLY"),IF(OR($G14="Dr",$G14="Cr"),"OK","INVALID - must derive"),IF(OR($G14="n/a",$G14="runtime"),"OK","INVALID - must be n/a"))) -> OK | N14: {=IF($J14="MIRROR",IF($F14="MIRRORED","OK","INVALID - MIRROR needs MIRRORED"),IF(IFERROR(INDEX(Amount_Basis!$D$5:$D$100,MATCH($H14,Amount_Basis!$A$5:$A$100,0)),"")="SIGNED",IF($F14="DERIVED_FROM_SIGN","OK","INVALID - SIGNED basis needs DERIVED_FROM_SIGN"),IF(OR($F14="INCREASE",$F14="DECREASE",$F14="—"),"OK","INVALID - static direction required")))} -> OK | O14: §3.2
A15: Import | B15: LC_AMD_INC | C15: DEFER_COMMISSION | D15: 2 | E15: CUSTOMER_CURRENT_ACCOUNT | F15: DECREASE | G15: {=IF(OR($F15="DERIVED_FROM_SIGN",$F15="MIRRORED"),"runtime",IFERROR(IF(INDEX(Balance_Taxonomy!$C$5:$C$400,MATCH($E15,Balance_Taxonomy!$B$5:$B$400,0))="Dr",IF($F15="INCREASE","Dr","Cr"),IF($F15="INCREASE","Cr","Dr")),"n/a"))} -> Dr | H15: COMMISSION_DELTA | I15: incremental commission | J15: POST | K15: =IF(OR($E15="—",LEFT($E15,1)="("),"n/a",IF(COUNTIF(Balance_Taxonomy!$B$5:$B$400,$E15)>0,"OK","UNKNOWN TYPE")) -> OK | L15: =IF(COUNTIF(Amount_Basis!$A$5:$A$100,$H15)>0,"OK","UNKNOWN CODE") -> OK | M15: =IF($F15="DERIVED_FROM_SIGN",IF($G15="runtime","OK","INVALID - must be runtime"),IF(OR($J15="POST",$J15="MEMO_ONLY"),IF(OR($G15="Dr",$G15="Cr"),"OK","INVALID - must derive"),IF(OR($G15="n/a",$G15="runtime"),"OK","INVALID - must be n/a"))) -> OK | N15: {=IF($J15="MIRROR",IF($F15="MIRRORED","OK","INVALID - MIRROR needs MIRRORED"),IF(IFERROR(INDEX(Amount_Basis!$D$5:$D$100,MATCH($H15,Amount_Basis!$A$5:$A$100,0)),"")="SIGNED",IF($F15="DERIVED_FROM_SIGN","OK","INVALID - SIGNED basis needs DERIVED_FROM_SIGN"),IF(OR($F15="INCREASE",$F15="DECREASE",$F15="—"),"OK","INVALID - static direction required")))} -> OK | O15: §3.2
A16: Import | B16: LC_AMD_INC | C16: DEFER_COMMISSION | D16: 2 | E16: UNEARNED_COMMISSION_INCOME | F16: INCREASE | G16: {=IF(OR($F16="DERIVED_FROM_SIGN",$F16="MIRRORED"),"runtime",IFERROR(IF(INDEX(Balance_Taxonomy!$C$5:$C$400,MATCH($E16,Balance_Taxonomy!$B$5:$B$400,0))="Dr",IF($F16="INCREASE","Dr","Cr"),IF($F16="INCREASE","Cr","Dr")),"n/a"))} -> Cr | H16: COMMISSION_DELTA | I16: incremental commission | J16: POST | K16: =IF(OR($E16="—",LEFT($E16,1)="("),"n/a",IF(COUNTIF(Balance_Taxonomy!$B$5:$B$400,$E16)>0,"OK","UNKNOWN TYPE")) -> OK | L16: =IF(COUNTIF(Amount_Basis!$A$5:$A$100,$H16)>0,"OK","UNKNOWN CODE") -> OK | M16: =IF($F16="DERIVED_FROM_SIGN",IF($G16="runtime","OK","INVALID - must be runtime"),IF(OR($J16="POST",$J16="MEMO_ONLY"),IF(OR($G16="Dr",$G16="Cr"),"OK","INVALID - must derive"),IF(OR($G16="n/a",$G16="runtime"),"OK","INVALID - must be n/a"))) -> OK | N16: {=IF($J16="MIRROR",IF($F16="MIRRORED","OK","INVALID - MIRROR needs MIRRORED"),IF(IFERROR(INDEX(Amount_Basis!$D$5:$D$100,MATCH($H16,Amount_Basis!$A$5:$A$100,0)),"")="SIGNED",IF($F16="DERIVED_FROM_SIGN","OK","INVALID - SIGNED basis needs DERIVED_FROM_SIGN"),IF(OR($F16="INCREASE",$F16="DECREASE",$F16="—"),"OK","INVALID - static direction required")))} -> OK | O16: §3.2
... A222: Cross | B222: EVT_REVERSE | C222: SIGNED_REVERSAL | D222: 1 | E222: (mirror of the reversed event) | F222: MIRRORED | G222: {=IF(OR($F222="DERIVED_FROM_SIGN",$F222="MIRRORED"),"runtime",IFERROR(IF(INDEX(Balance_Taxonomy!$C$5:$C$400,MATCH($E222,Balance_Taxonomy!$B$5:$B$400,0))="Dr",IF($F222="INCREASE","Dr","Cr"),IF($F222="INCREASE","Cr","Dr")),"n/a"))} -> runtime | H222: ORIGINAL_AMOUNT_SIGNED | I222: original amount, signed | J222: MIRROR | K222: =IF(OR($E222="—",LEFT($E222,1)="("),"n/a",IF(COUNTIF(Balance_Taxonomy!$B$5:$B$400,$E222)>0,"OK","UNKNOWN TYPE")) -> n/a | L222: =IF(COUNTIF(Amount_Basis!$A$5:$A$100,$H222)>0,"OK","UNKNOWN CODE") -> OK | M222: =IF($F222="DERIVED_FROM_SIGN",IF($G222="runtime","OK","INVALID - must be runtime"),IF(OR($J222="POST",$J222="MEMO_ONLY"),IF(OR($G222="Dr",$G222="Cr"),"OK","INVALID - must derive"),IF(OR($G222="n/a",$G222="runtime"),"OK","INVALID - must be n/a"))) -> OK | N222: {=IF($J222="MIRROR",IF($F222="MIRRORED","OK","INVALID - MIRROR needs MIRRORED"),IF(IFERROR(INDEX(Amount_Basis!$D$5:$D$100,MATCH($H222,Amount_Basis!$A$5:$A$100,0)),"")="SIGNED",IF($F222="DERIVED_FROM_SIGN","OK","INVALID - SIGNED basis needs DERIVED_FROM_SIGN"),IF(OR($F222="INCREASE",$F222="DECREASE",$F222="—"),"OK","INVALID - static direction required")))} -> OK | O222: §9.6

Sheet Amount_Basis
A1: Amount basis catalogue — the machine contract
A2: I22 — movement owns DIRECTION, amount_basis_code owns MAGNITUDE. NON_NEGATIVE bases pair with INCREASE/DECREASE; SIGNED bases MUST use movement = DERIVED_FROM_SIGN and may never pair with a static direction. A resolver is a PURE FUNCTION of (event, undertaking, config, balances-at-event-time); declared dependencies fix evaluation order. Codes are VERSIONED with the L2 mapping — changing a resolver's meaning is a new code, never an edit.
A4: amount_basis_code | B4: Resolver | C4: Inputs | D4: sign_contract | E4: Note
A5: DOCUMENT_AMOUNT | B5: event.amount | C5: event | D5: NON_NEGATIVE | E5: Presented/complying document amount. The most-used basis.
A6: MAX_LIABILITY | B6: undertaking.max_liability | C6: undertaking | D6: NON_NEGATIVE | E6: Art. 30(a) amount tolerance only — never 30(b) quantity.
A7: AMENDMENT_DELTA | B7: ABS(event.delta_amount) | C7: event | D7: NON_NEGATIVE | E7: MAGNITUDE ONLY (I22). Direction comes from movement — never from the sign. Test T37.
A8: CONFIRMED_AMOUNT | B8: undertaking.confirmed_amount | C8: undertaking | D8: NON_NEGATIVE | E8: INDEPENDENT of lc_amount (I13).
A9: ACCEPTANCE_AMOUNT | B9: undertaking.acceptance_amount | C9: undertaking | D9: NON_NEGATIVE | E9: Face of the accepted draft / incurred DPU.
A10: MARGIN_TAKEN | B10: undertaking.face_amount x config.margin_pct | C10: undertaking, config | D10: NON_NEGATIVE | E10: At issuance.
A11: MARGIN_APPLIED | B11: DOCUMENT_AMOUNT x config.margin_pct | C11: event, config | D11: NON_NEGATIVE | E11: PRO RATA to utilisation. Never the full margin on a partial drawing (T1).
A12: MARGIN_RESIDUAL | B12: balance(LC_CASH_MARGIN_DEPOSIT) at event time | C12: balances | D12: NON_NEGATIVE | E12: Released at expiry/cancellation.
A13: CUSTOMER_FUNDING_REMAINDER | B13: DOCUMENT_AMOUNT - MARGIN_APPLIED | C13: derived | D13: NON_NEGATIVE | E13: DEPENDS ON MARGIN_APPLIED — evaluation order enforced by the engine.
A14: RESIDUAL_OUTSTANDING | B14: balance(<undertaking outstanding>) at event time | C14: balances | D14: NON_NEGATIVE | E14: Expiry, cancellation, recourse.
A15: POLICY_NOTIONAL | B15: invoice x config.sg_uplift_pct (or sg_unlimited_policy_notional_pct) | C15: config | D15: NON_NEGATIVE | E15: SG / AWB where the carrier form is unlimited.
... A36: ZERO | B36: 0 | C36: — | D36: n/a | E36: Non-posting events; declared explicitly, never inferred from absence (I17).

Sheet L1_L2_Coverage
A1: Gates G2 / G2B / G10 / G13 — resolution, posting-side, amount-basis, amount-direction
A2: Live formulas. Any non-zero failure figure BLOCKS THE BUILD. G2B is a PER-ROW semantic rule keyed on movement_type — not a count of n/a rows, which can mask a lost n/a against a failed derivation. Green cells are formulas.
A4: Check | B4: Value
A5: L1 events defined | B5: =COUNTA(L1_Event_Catalogue!$B$5:$B$400) -> 57
A6: L1 events with at least one L2 row | B6: =COUNTIF(L1_Event_Catalogue!$I$5:$I$400,"OK") -> 57
A7: Gaps (must be 0) | B7: =B5-B6 -> 0
A8: L2 rows total | B8: =COUNTA(L2_Balance_Movement!$B$5:$B$600) -> 218
A9: L2 rows with an unknown balance_type (must be 0) | B9: =COUNTIF(L2_Balance_Movement!$K$5:$K$600,"UNKNOWN TYPE") -> 0
A10: L2 rows with an unknown amount_basis_code (must be 0) [G10] | B10: =COUNTIF(L2_Balance_Movement!$L$5:$L$600,"UNKNOWN CODE") -> 0
A11: L2 rows failing posting-side integrity (must be 0) [G2B] | B11: =COUNTIF(L2_Balance_Movement!$M$5:$M$600,"INVALID*") -> 0
A12: L2 rows failing amount-direction integrity (must be 0) [G13] | B12: =COUNTIF(L2_Balance_Movement!$N$5:$N$600,"INVALID*") -> 0
A13: Amount_Basis codes defined | B13: =COUNTA(Amount_Basis!$A$5:$A$100) -> 32
A14: Amount_Basis codes unused in L2 (dead configuration) | B14: =SUMPRODUCT((Amount_Basis!$A$5:$A$100<>"")*(COUNTIF(L2_Balance_Movement!$H$5:$H$600,Amount_Basis!$A$5:$A$100&"")=0)) -> 0
A15: GATE G2 / G2B / G10 / G13 RESULT | B15: =IF(AND(B7=0,B9=0,B10=0,B11=0,B12=0,B14=0),"PASS","FAIL — BLOCK BUILD") -> PASS

Sheet L3_GL_Mapping
A1: LAYER 3 — GL mapping template
A2: Row 5 is a worked EXAMPLE showing the expected format — replace it. Rules A1-A6: an unresolved mapping REJECTS the posting, never a suspense account. Gate G1 blocks production until coverage is 100%.
A4: entity (EDIT) | B4: balance_type | C4: balance_class | D4: ccy (EDIT) | E4: product (EDIT) | F4: gl_account (EDIT) | G4: gl_name (EDIT) | H4: effective_from (EDIT) | I4: Mapped?
A5: HK01 | B5: LC_OUTSTANDING | C5: CONTINGENT | D5: USD | E5: IMPORT_LC | F5: 991010 | G5: Documentary Credits Outstanding — Sight | H5: 2026-01-01 | I5: =IF(COUNTBLANK($A5:$H5)=0,"OK","INCOMPLETE") -> OK
B6: LC_CUSTOMER_LIABILITY | C6: CONTINGENT | I6: =IF(COUNTBLANK($A6:$H6)=0,"OK","INCOMPLETE") -> INCOMPLETE
B7: SG_CUSTOMER_LIABILITY | C7: CONTINGENT | I7: =IF(COUNTBLANK($A7:$H7)=0,"OK","INCOMPLETE") -> INCOMPLETE
B8: SG_OUTSTANDING | C8: CONTINGENT | I8: =IF(COUNTBLANK($A8:$H8)=0,"OK","INCOMPLETE") -> INCOMPLETE
B9: CONFIRMATION_EXPOSURE | C9: CONTINGENT | I9: =IF(COUNTBLANK($A9:$H9)=0,"OK","INCOMPLETE") -> INCOMPLETE
B10: CONFIRMATION_OUTSTANDING | C10: CONTINGENT | I10: =IF(COUNTBLANK($A10:$H10)=0,"OK","INCOMPLETE") -> INCOMPLETE
B11: REIMB_UNDERTAKING_EXPOSURE | C11: CONTINGENT | I11: =IF(COUNTBLANK($A11:$H11)=0,"OK","INCOMPLETE") -> INCOMPLETE
B12: REIMB_UNDERTAKING_OUTSTANDING | C12: CONTINGENT | I12: =IF(COUNTBLANK($A12:$H12)=0,"OK","INCOMPLETE") -> INCOMPLETE
B13: IMPORT_BILLS_RECEIVABLE | C13: ON_BALANCE_ASSET | I13: =IF(COUNTBLANK($A13:$H13)=0,"OK","INCOMPLETE") -> INCOMPLETE
B14: ACCEPTANCE_REIMB_RECEIVABLE_APPLICANT | C14: ON_BALANCE_ASSET | I14: =IF(COUNTBLANK($A14:$H14)=0,"OK","INCOMPLETE") -> INCOMPLETE
B15: ACCEPTANCE_REIMB_RECEIVABLE_ISSUING_BANK | C15: ON_BALANCE_ASSET | I15: =IF(COUNTBLANK($A15:$H15)=0,"OK","INCOMPLETE") -> INCOMPLETE
B16: IMPORT_USANCE_FINANCING | C16: ON_BALANCE_ASSET | I16: =IF(COUNTBLANK($A16:$H16)=0,"OK","INCOMPLETE") -> INCOMPLETE
B17: IMPORT_USANCE_RECEIVABLE_APPLICANT | C17: ON_BALANCE_ASSET | I17: =IF(COUNTBLANK($A17:$H17)=0,"OK","INCOMPLETE") -> INCOMPLETE
... B55: FX_REVALUATION | C55: PROFIT_AND_LOSS | I55: =IF(COUNTBLANK($A55:$H55)=0,"OK","INCOMPLETE") -> INCOMPLETE
A58: A4: the balance_type -> gl_account relationship is MANY-TO-MANY. Do not assume 1:1. A2: MEMO_ONLY maps only to memorandum GL ranges. A3: CONTINGENT only to off-BS ranges, in Dr/Cr pairs.

Sheet GL_Coverage
A1: Gate G1 — GL mapping completeness
A2: No promotion to production while any mandatory gap remains. Coverage updates live as the BA completes L3_GL_Mapping.
A4: Check | B4: Value
A5: Mapping rows required (this template) | B5: =COUNTA(L3_GL_Mapping!$B$5:$B$400) -> 51
A6: Mapping rows completed | B6: =COUNTIF(L3_GL_Mapping!$I$5:$I$400,"OK") -> 1
A7: Missing | B7: =B5-B6 -> 50
A8: Coverage | B8: =IF(B5=0,0,B6/B5) -> 0.019607843
A9: GATE G1 RESULT | B9: =IF(B7=0,"PASS","FAIL — BLOCK PRODUCTION") -> FAIL — BLOCK PRODUCTION
A12: Production validator — the full expansion this template stands in for:
A13: For every ENABLED combination entity x product x currency x event_code x balance_type,
A14: a GL mapping must exist. Required count = SUM over enabled entities of
A15: (products x currencies x distinct balance_types reachable from L2 for those products).
A17: Failure output:
A18: MISSING_GL_MAPPING
A19: Entity: TW01 | Product: IMPORT_LC | Currency: JPY
A20: Balance Type: ACCEPTANCE_DPU_OUTSTANDING | Triggered by: LC_ACCEPT

Sheet Tenor_Derivation
A1: Tenor model — business classification vs accounting drivers
A2: tenorType is retained for product setup, UI and MIS. It is NEVER read by accounting, risk or regulatory logic (V1, build-breaking static check). Derivation requires operator confirmation and carries provenance — spec §4.3.
A4: Side | B4: tenorType (business/UI) | C4: undertakingAvailability | D4: financingStructure | E4: fundingParty | F4: availableWith | G4: Honour event | H4: Accounting result | I4: v2 ref | J4: Provenance
A5: Import | B5: SIGHT | C5: SIGHT | D5: NONE | E5: — | F5: — | G5: LC_HONOUR_SIGHT | H5: Bills receivable + settlement payable | I5: §3.5 | J5: derived_from_tenor_type / derivation_rule_version / operator_confirmed_by / _at / overridden / override_reason
A6: Import | B6: BUYERS_USANCE | C6: SIGHT | D6: BUYER_USANCE | E6: SELF | F6: — | G6: LC_HONOUR_BU_A | H6: Import usance financing (applicant) | I6: §3.6 | J6: derived_from_tenor_type / derivation_rule_version / operator_confirmed_by / _at / overridden / override_reason
A7: Import | B7: BUYERS_USANCE | C7: SIGHT | D7: BUYER_USANCE | E7: REFINANCING_BANK | F7: — | G7: LC_HONOUR_BU_B | H7: Applicant receivable AND due to refinancing bank | I7: §3.6 | J7: derived_from_tenor_type / derivation_rule_version / operator_confirmed_by / _at / overridden / override_reason
A8: Import | B8: SELLERS_USANCE | C8: ACCEPTANCE | D8: SELLER_USANCE | E8: — | F8: — | G8: LC_ACCEPT | H8: On-BS acceptance liability + reimbursement receivable | I8: §3.7 | J8: derived_from_tenor_type / derivation_rule_version / operator_confirmed_by / _at / overridden / override_reason
A9: Import | B9: SELLERS_USANCE | C9: DEF_PAYMENT | D9: SELLER_USANCE | E9: — | F9: — | G9: LC_ACCEPT | H9: As above; instrumentType = DPU | I9: §3.7 | J9: derived_from_tenor_type / derivation_rule_version / operator_confirmed_by / _at / overridden / override_reason
A10: Import | B10: (any) | C10: (any) | D10: BUYER_USANCE | E10: APPLICANT | F10: — | G10: REJECT AT VALIDATION | H10: fundingParty = APPLICANT does not exist. Buyer's usance is defined by the buyer bearing the discount cost. | I10: §3.6 | J10: derived_from_tenor_type / derivation_rule_version / operator_confirmed_by / _at / overridden / override_reason
A11: Export | B11: SIGHT | C11: SIGHT | D11: — | E11: — | F11: any | G11: CNF_HONOUR_SIGHT | H11: Due from issuing bank, no recourse | I11: §7.4a | J11: derived_from_tenor_type / derivation_rule_version / operator_confirmed_by / _at / overridden / override_reason
A12: Export | B12: BUYERS_USANCE | C12: SIGHT or NEGOTIATION | D12: — | E12: — | F12: ISSUING_BANK / ANY_BANK | G12: CNF_HONOUR_BU | H12: Due from issuing bank AT SIGHT. No deferred receivable. | I12: §7.5 | J12: derived_from_tenor_type / derivation_rule_version / operator_confirmed_by / _at / overridden / override_reason
A13: Export | B13: BUYERS_USANCE | C13: ACCEPTANCE / DEF_PAYMENT | D13: — | E13: — | F13: THIS_BANK | G13: CNF_ACCEPT | H13: Reimbursement due AT MATURITY (Art. 7(c)) | I13: §7.5 | J13: derived_from_tenor_type / derivation_rule_version / operator_confirmed_by / _at / overridden / override_reason
A14: Export | B14: SELLERS_USANCE | C14: ACCEPTANCE / DEF_PAYMENT | D14: — | E14: — | F14: THIS_BANK | G14: CNF_ACCEPT | H14: On-BS acceptance liability + issuing-bank receivable | I14: §7.6 | J14: derived_from_tenor_type / derivation_rule_version / operator_confirmed_by / _at / overridden / override_reason
A15: Export | B15: SELLERS_USANCE | C15: ACCEPTANCE / DEF_PAYMENT | D15: — | E15: — | F15: ISSUING_BANK | G15: (no event) | H15: Issuing bank's acceptance only fixes the maturity date. Test T14. | I15: §7.6 | J15: derived_from_tenor_type / derivation_rule_version / operator_confirmed_by / _at / overridden / override_reason
... A17: Export | B17: (any) | C17: (any) | D17: — | E17: — | F17: any | G17: (none) | H17: bankRole = ADVISING: no contingent, no asset | I17: §6 | J17: derived_from_tenor_type / derivation_rule_version / operator_confirmed_by / _at / overridden / override_reason

Sheet L4_Risk_Obligor
A1: LAYER 4 — Risk: obligor, EAD, staging
A2: Risk reads the ledger; it never writes to it. I9: ecl_ead_factor and ccf_regulatory are never read from the same field. See spec §8.5 for the five separately-named exposure outputs.
A4: Product / event | B4: obligor_party | C4: obligor_type | D4: recourse | E4: Limit consumed | F4: Note | G4: v2 ref
A5: Import LC, SG, acceptance, all import financing | B5: Applicant | C5: CORPORATE | D5: FALSE | E5: Customer trade limit | G5: §10.1
A6: Export confirmation, confirmed acceptance, discounted export bill | B6: Issuing bank | C6: FI | D6: FALSE | E6: FI limit + COUNTRY limit | F6: Not the exporter's limit — the practical reason for the Issuing Bank Confirmation Exposure naming. | G6: §7.1
A7: Refinancing loan to issuing bank (EX_REFIN) | B7: Issuing bank | C7: FI | D7: FALSE | E7: FI limit + country | F7: Separate FI credit approval. | G7: §7.5
A8: Reimbursement undertaking (RMB_UNDERTAKE) | B8: Issuing bank | C8: FI | D8: FALSE | E8: FI limit + country | G8: §7.7
A9: EX_NEGOTIATE (unconfirmed negotiation) | B9: Exporter | C9: CORPORATE | D9: TRUE | E9: Exporter limit | F9: Issuing bank is the secondary source only. | G9: §7.4b
A10: EX_PAY_RESERVE | B10: Exporter | C10: CORPORATE | D10: TRUE | E10: Exporter limit | G10: §7.3
A11: LC_PAY_RESERVE | B11: Presenter / beneficiary | C11: FI or CORPORATE | D11: TRUE | E11: Counterparty limit | F11: Reclassify to a normal applicant receivable once discrepancies are accepted. | G11: §3.4
A12: ALL — general rule | B12: read obligor_party off the EVENT | C12: — | D12: — | E12: follows the obligor | F12: There is NO 'never the beneficiary' rule. Hard-coding one misassigns PD/LGD on the riskiest sub-book. | G12: §9.3

Sheet L5_Regulatory_CCF
A1: LAYER 5 — Regulatory: CCF and ccf_source
A2: I10: regulatory returns read ONLY ccf_source = REGULATORY. Internal-policy re-weights feed ead_economic and management reporting, never a supervisory return.
A4: ccf_class | B4: CCF | C4: ccf_source | D4: Applies to | E4: Basis / caveat | F4: v2 ref
A5: TRADE_20 | B5: 20% | C5: REGULATORY | D5: Import LC; export confirmation — short-term self-liquidating, collateralised by the shipment | E5: Basel III CRE20. | F5: §10.3
A6: PERF_50 | B6: 50% | C6: REGULATORY | D6: Performance guarantees and performance standbys | E6: CRE20. | F6: §10.3
A7: DIRECT_CREDIT_SUB_100 | B7: 100% | C7: REGULATORY | D7: Financial standbys; avalisation of drafts | E7: CRE20. | F7: §10.3
A8: COMMITMENT_40 | B8: 40% | C8: REGULATORY | D8: Advised commitments | E8: CRE20. | F8: §10.3
A9: UCC_10 | B9: 10% | C9: REGULATORY | D9: Advised, unconditionally cancellable commitments | E9: Basel III raised UCC from 0% to 10%. The Basel II 0% treatment is SUPERSEDED. | F9: §10.3
A10: SG_DCS_100 | B10: 100% | C10: INTERNAL_POLICY | D10: Shipping guarantee / delivery order endorsement | E10: CRE20 does not name shipping guarantees. Reasoned position: an unconditional indemnity to a carrier. | F10: §10.3
A11: LC_POST_SG_100 | B11: 100% | C11: INTERNAL_POLICY | D11: LC covered by an SG — covered portion only | E11: CRE20 contains NO such reclassification. Basis: the 20% CCF is conditioned on the credit being self-liquidating and collateralised by the shipment; once the goods are released that condition fails. Agree with your supervisor. | F11: §10.3
A12: RMB_UNDERTAKING | B12: 100% pending supervisory confirmation | C12: INTERNAL_POLICY | D12: URR 725 reimbursement undertaking | E12: The reimbursing bank never sees the shipping documents, so the 'collateralised by the shipment' precondition for the 20% class fails. Do not default to 20%. | F12: §10.3
A13: (n/a — on balance sheet) | B13: — | C13: — | D13: Acceptances and incurred DPUs | E13: NOT an off-BS item at all. Risk-weight as a funded claim on the obligor. | F13: §3.7
A14: (none) | B14: — | C14: — | D14: Unadvised line | E14: Not a 'commitment' under CRE20 — no arrangement offered AND accepted. Attracts nothing. | F14: §10.3

Sheet Invariants
A1: Invariants — the correctness contract
A2: Enforced in code at the transaction boundary. Not in reporting, not in review. Hard-coded engine behaviour (E4) and not configurable. Sorted numerically — this sheet is a code-generation input.
A4: ID | B4: Invariant | C4: Enforced at | D4: Why / failure mode
A5: I1A | B5: Journal balance: Sum Dr = Sum Cr per posting_transaction_id per currency, always | C5: Posting layer | D5: Scope is the JOURNAL — not the class, not the undertaking. A per-class rule would reject the acceptance pair, whose Dr is an ON_BALANCE_ASSET and Cr an ON_BALANCE_LIABILITY by design.
A6: I1B | B6: Contingent memo pair: contra and outstanding legs equal and opposite per undertaking_id per currency | C6: Posting layer + daily control | D6: The cheapest defect detector in the system.
A7: I1C | B7: MEMO_ONLY pair reconciles per undertaking_id per currency | C7: Daily control | D7: A drifted shadow pair is a defect in the shadow — never a reason to adjust the accounting record.
A8: I2 | B8: A TRANSFORM release and its paired create commit in ONE transaction, or neither commits | C8: Transaction boundary | D8: Double-count during the window between the two postings. Test T25.
A9: I3 | B9: No contingent balance may go negative | C9: Posting layer | D9: Over-release masks a stranded balance elsewhere. NOT a substitute for I16.
